Traceback (most recent call last):
  File "/home/tiepvu/w/tabml_book/tabml_book_env/lib/python3.8/site-packages/jupyter_cache/executors/utils.py", line 51, in single_nb_execution
    executenb(
  File "/home/tiepvu/w/tabml_book/tabml_book_env/lib/python3.8/site-packages/nbclient/client.py", line 1112, in execute
    return NotebookClient(nb=nb, resources=resources, km=km, **kwargs).execute()
  File "/home/tiepvu/w/tabml_book/tabml_book_env/lib/python3.8/site-packages/nbclient/util.py", line 74, in wrapped
    return just_run(coro(*args, **kwargs))
  File "/home/tiepvu/w/tabml_book/tabml_book_env/lib/python3.8/site-packages/nbclient/util.py", line 53, in just_run
    return loop.run_until_complete(coro)
  File "/usr/lib/python3.8/asyncio/base_events.py", line 616, in run_until_complete
    return future.result()
  File "/home/tiepvu/w/tabml_book/tabml_book_env/lib/python3.8/site-packages/nbclient/client.py", line 553, in async_execute
    await self.async_execute_cell(
  File "/home/tiepvu/w/tabml_book/tabml_book_env/lib/python3.8/site-packages/nbclient/client.py", line 857, in async_execute_cell
    self._check_raise_for_error(cell, exec_reply)
  File "/home/tiepvu/w/tabml_book/tabml_book_env/lib/python3.8/site-packages/nbclient/client.py", line 760, in _check_raise_for_error
    raise CellExecutionError.from_cell_and_msg(cell, exec_reply_content)
nbclient.exceptions.CellExecutionError: An error occurred while executing the following cell:
------------------
import seaborn as sns
from sklearn.manifold import TSNE

movie_subset_embs.shape
movie_2d = TSNE(n_components=2, init='pca').fit_transform(movie_subset_embs)
movie_df = pd.DataFrame(
    data={
        "x": movie_2d[:, 0],
        "y": movie_2d[:, 1],
        "genre": movie_genres[movie_inds_one_genre],
    }
)

plt.figure(figsize=(20, 20))
ax = sns.scatterplot(x="x", y="y", hue='genre',data=movie_df)
------------------

[0;31m---------------------------------------------------------------------------[0m
[0;31mNameError[0m                                 Traceback (most recent call last)
[0;32m<ipython-input-11-c3c7331aab2a>[0m in [0;36m<module>[0;34m[0m
[1;32m     12[0m )
[1;32m     13[0m [0;34m[0m[0m
[0;32m---> 14[0;31m [0mplt[0m[0;34m.[0m[0mfigure[0m[0;34m([0m[0mfigsize[0m[0;34m=[0m[0;34m([0m[0;36m20[0m[0;34m,[0m [0;36m20[0m[0;34m)[0m[0;34m)[0m[0;34m[0m[0;34m[0m[0m
[0m[1;32m     15[0m [0max[0m [0;34m=[0m [0msns[0m[0;34m.[0m[0mscatterplot[0m[0;34m([0m[0mx[0m[0;34m=[0m[0;34m"x"[0m[0;34m,[0m [0my[0m[0;34m=[0m[0;34m"y"[0m[0;34m,[0m [0mhue[0m[0;34m=[0m[0;34m'genre'[0m[0;34m,[0m[0mdata[0m[0;34m=[0m[0mmovie_df[0m[0;34m)[0m[0;34m[0m[0;34m[0m[0m

[0;31mNameError[0m: name 'plt' is not defined
NameError: name 'plt' is not defined

